<?xml version="1.0" ?>
<!-- =================================================================================== -->
<!-- |    This document was autogenerated by xacro from mecabot.urdf.xacro             | -->
<!-- |    EDITING THIS FILE BY HAND IS NOT RECOMMENDED                                 | -->
<!-- =================================================================================== -->
<robot name="mecabot">
  <!-- in kg-->
  <material name="black">
    <color rgba="0.0 0.0 0.0 1.0"/>
  </material>
  <material name="red">
    <color rgba="0.8 0.0 0.0 1.0"/>
  </material>
  <material name="green">
    <color rgba="0.0 0.8 0.0 1.0"/>
  </material>
  <material name="blue">
    <color rgba="0.0 0.0 0.8 1.0"/>
  </material>
  <material name="yellow">
    <color rgba="0.9686274509803922 0.9294117647058824 0.19215686274509805 1.0"/>
  </material>
  <material name="orange">
    <color rgba="1.0 0.4235294117647059 0.0392156862745098 1.0"/>
  </material>
  <material name="brown">
    <color rgba="0.8705882352941177 0.8117647058823529 0.7647058823529411 1.0"/>
  </material>
  <material name="grey">
    <color rgba="0.2 0.2 0.2 1.0"/>
  </material>
  <material name="white">
    <color rgba="1.0 1.0 1.0 1.0"/>
  </material>
  <!-- BASE LINK -->
  <link name="base_link">
    <collision>
      <origin rpy="0.0 0.0 0.0" xyz="0.0 0.0 0.035"/>
      <geometry>
        <box size="0.255 0.15 0.07"/>
      </geometry>
    </collision>
  </link>
  <link name="lower_layer_link">
    <visual>
      <origin rpy="0 0 0" xyz="0 0 0"/>
      <geometry>
        <box size="0.255 0.088 0.002"/>
      </geometry>
      <material name="blue">
        <color rgba="0.0 0.2 1.0 1.0"/>
      </material>
    </visual>
    <visual name="FL_motor">
      <origin rpy="0.0 0.0 0.0" xyz="0.04 0.034 -0.009"/>
      <geometry>
        <box size="0.07 0.022 0.018"/>
      </geometry>
      <material name="motor">
        <color rgba="0.9686274509803922 0.7843137254901961 0.23529411764705882 1.0"/>
      </material>
    </visual>
    <visual name="FR_motor">
      <origin rpy="0.0 0.0 0.0" xyz="0.04 -0.034 -0.009"/>
      <geometry>
        <box size="0.07 0.022 0.018"/>
      </geometry>
      <material name="motor">
        <color rgba="0.9686274509803922 0.7843137254901961 0.23529411764705882 1.0"/>
      </material>
    </visual>
    <visual name="BL_motor">
      <origin rpy="0.0 0.0 0.0" xyz="-0.04 0.034 -0.009"/>
      <geometry>
        <box size="0.07 0.022 0.018"/>
      </geometry>
      <material name="motor">
        <color rgba="0.9686274509803922 0.7843137254901961 0.23529411764705882 1.0"/>
      </material>
    </visual>
    <visual name="BR_motor">
      <origin rpy="0.0 0.0 0.0" xyz="-0.04 -0.034 -0.009"/>
      <geometry>
        <box size="0.07 0.022 0.018"/>
      </geometry>
      <material name="motor">
        <color rgba="0.9686274509803922 0.7843137254901961 0.23529411764705882 1.0"/>
      </material>
    </visual>
    <!-- Top left piece -->
    <visual>
      <origin rpy="0.0 0.0 0.0" xyz="0.1125 0.059 0"/>
      <geometry>
        <box size="0.03 0.03 0.002"/>
      </geometry>
      <material name="blue">
        <color rgba="0.0 0.2 1.0 1.0"/>
      </material>
    </visual>
    <!-- Top right piece -->
    <visual>
      <origin rpy="0.0 0.0 0.0" xyz="0.1125 -0.059 0"/>
      <geometry>
        <box size="0.03 0.03 0.002"/>
      </geometry>
      <material name="blue">
        <color rgba="0.0 0.2 1.0 1.0"/>
      </material>
    </visual>
    <!-- Middle left piece -->
    <visual>
      <origin rpy="0.0 0.0 0.0" xyz="0.0 0.059 0"/>
      <geometry>
        <box size="0.054 0.03 0.002"/>
      </geometry>
      <material name="blue">
        <color rgba="0.0 0.2 1.0 1.0"/>
      </material>
    </visual>
    <!-- Middle right piece -->
    <visual>
      <origin rpy="0.0 0.0 0.0" xyz="0.0 -0.059 0"/>
      <geometry>
        <box size="0.054 0.03 0.002"/>
      </geometry>
      <material name="blue">
        <color rgba="0.0 0.2 1.0 1.0"/>
      </material>
    </visual>
    <!-- Bottom left piece -->
    <visual>
      <origin rpy="0.0 0.0 0.0" xyz="-0.1125 0.059 0"/>
      <geometry>
        <box size="0.03 0.03 0.002"/>
      </geometry>
      <material name="blue">
        <color rgba="0.0 0.2 1.0 1.0"/>
      </material>
    </visual>
    <!-- Bottom right piece -->
    <visual>
      <origin rpy="0.0 0.0 0.0" xyz="-0.1125 -0.059 0"/>
      <geometry>
        <box size="0.03 0.03 0.002"/>
      </geometry>
      <material name="blue">
        <color rgba="0.0 0.2 1.0 1.0"/>
      </material>
    </visual>
    <collision>
      <origin rpy="0 0 0" xyz="0 0 0"/>
      <geometry>
        <box size="0.255 0.148 0.002"/>
      </geometry>
    </collision>
    <inertial>
      <origin rpy="0.0 0.0 0.0" xyz="0.0 0.0 0.0"/>
      <mass value="0.07"/>
      <inertia ixx="4.519666666666666e-05" ixy="0.0" ixz="0.0" iyy="0.0003793358333333334" iyz="0.0" izz="0.0004244858333333334"/>
    </inertial>
  </link>
  <joint name="base_to_lower_layer_joint" type="fixed">
    <parent link="base_link"/>
    <child link="lower_layer_link"/>
    <origin rpy="0 0 0" xyz="0 0 0.0"/>
  </joint>
  <gazebo reference="lower_layer_link">
    <material>Gazebo/Blue</material>
    <visual name="direction_piece_1">
      <material>
        <diffuse>0 0 0 1</diffuse>
      </material>
    </visual>
    <visual name="direction_piece_2">
      <material>Gazebo/Red</material>
    </visual>
    <visual name="direction_piece_3">
      <material>Gazebo/Red</material>
    </visual>
  </gazebo>
  <link name="pillar_one_link">
    <visual>
      <origin rpy="0.0 0.0 0.0" xyz="0.0 0.0 0.0275"/>
      <geometry>
        <cylinder length="0.055" radius="0.002"/>
      </geometry>
      <material name="pillar_color">
        <color rgba="1.0 0.4235294117647059 0.047058823529411764 1.0"/>
      </material>
    </visual>
    <collision>
      <origin rpy="0.0 0.0 0.0" xyz="0.0 0.0 0.0275"/>
      <geometry>
        <cylinder length="0.055" radius="0.002"/>
      </geometry>
    </collision>
    <inertial>
      <origin rpy="0.0 0.0 0.0" xyz="0.0 0.0 0.0275"/>
      <mass value="0.005"/>
      <inertia ixx="1.2654166666666665e-06" ixy="0.0" ixz="0.0" iyy="1.2654166666666665e-06" iyz="0.0" izz="1e-08"/>
    </inertial>
  </link>
  <joint name="base_to_pillar_one_joint" type="fixed">
    <parent link="base_link"/>
    <child link="pillar_one_link"/>
    <origin rpy="0.0 0.0 0.0" xyz="0.12 0.0 0.0"/>
  </joint>
  <gazebo reference="pillar_one_link">
    <material>Gazebo/Orange</material>
  </gazebo>
  <link name="pillar_two_link">
    <visual>
      <origin rpy="0.0 0.0 0.0" xyz="0.0 0.0 0.0275"/>
      <geometry>
        <cylinder length="0.055" radius="0.002"/>
      </geometry>
      <material name="pillar_color">
        <color rgba="1.0 0.4235294117647059 0.047058823529411764 1.0"/>
      </material>
    </visual>
    <collision>
      <origin rpy="0.0 0.0 0.0" xyz="0.0 0.0 0.0275"/>
      <geometry>
        <cylinder length="0.055" radius="0.002"/>
      </geometry>
    </collision>
    <inertial>
      <origin rpy="0.0 0.0 0.0" xyz="0.0 0.0 0.0275"/>
      <mass value="0.005"/>
      <inertia ixx="1.2654166666666665e-06" ixy="0.0" ixz="0.0" iyy="1.2654166666666665e-06" iyz="0.0" izz="1e-08"/>
    </inertial>
  </link>
  <joint name="base_to_pillar_two_joint" type="fixed">
    <parent link="base_link"/>
    <child link="pillar_two_link"/>
    <origin rpy="0.0 0.0 0.0" xyz="0.12 0.055 0.0"/>
  </joint>
  <gazebo reference="pillar_two_link">
    <material>Gazebo/Orange</material>
  </gazebo>
  <link name="pillar_three_link">
    <visual>
      <origin rpy="0.0 0.0 0.0" xyz="0.0 0.0 0.0275"/>
      <geometry>
        <cylinder length="0.055" radius="0.002"/>
      </geometry>
      <material name="pillar_color">
        <color rgba="1.0 0.4235294117647059 0.047058823529411764 1.0"/>
      </material>
    </visual>
    <collision>
      <origin rpy="0.0 0.0 0.0" xyz="0.0 0.0 0.0275"/>
      <geometry>
        <cylinder length="0.055" radius="0.002"/>
      </geometry>
    </collision>
    <inertial>
      <origin rpy="0.0 0.0 0.0" xyz="0.0 0.0 0.0275"/>
      <mass value="0.005"/>
      <inertia ixx="1.2654166666666665e-06" ixy="0.0" ixz="0.0" iyy="1.2654166666666665e-06" iyz="0.0" izz="1e-08"/>
    </inertial>
  </link>
  <joint name="base_to_pillar_three_joint" type="fixed">
    <parent link="base_link"/>
    <child link="pillar_three_link"/>
    <origin rpy="0.0 0.0 0.0" xyz="0.12 -0.055 0.0"/>
  </joint>
  <gazebo reference="pillar_three_link">
    <material>Gazebo/Orange</material>
  </gazebo>
  <link name="pillar_four_link">
    <visual>
      <origin rpy="0.0 0.0 0.0" xyz="0.0 0.0 0.0275"/>
      <geometry>
        <cylinder length="0.055" radius="0.002"/>
      </geometry>
      <material name="pillar_color">
        <color rgba="1.0 0.4235294117647059 0.047058823529411764 1.0"/>
      </material>
    </visual>
    <collision>
      <origin rpy="0.0 0.0 0.0" xyz="0.0 0.0 0.0275"/>
      <geometry>
        <cylinder length="0.055" radius="0.002"/>
      </geometry>
    </collision>
    <inertial>
      <origin rpy="0.0 0.0 0.0" xyz="0.0 0.0 0.0275"/>
      <mass value="0.005"/>
      <inertia ixx="1.2654166666666665e-06" ixy="0.0" ixz="0.0" iyy="1.2654166666666665e-06" iyz="0.0" izz="1e-08"/>
    </inertial>
  </link>
  <joint name="base_to_pillar_four_joint" type="fixed">
    <parent link="base_link"/>
    <child link="pillar_four_link"/>
    <origin rpy="0.0 0.0 0.0" xyz="-0.12 0.0 0.0"/>
  </joint>
  <gazebo reference="pillar_four_link">
    <material>Gazebo/Orange</material>
  </gazebo>
  <link name="pillar_five_link">
    <visual>
      <origin rpy="0.0 0.0 0.0" xyz="0.0 0.0 0.0275"/>
      <geometry>
        <cylinder length="0.055" radius="0.002"/>
      </geometry>
      <material name="pillar_color">
        <color rgba="1.0 0.4235294117647059 0.047058823529411764 1.0"/>
      </material>
    </visual>
    <collision>
      <origin rpy="0.0 0.0 0.0" xyz="0.0 0.0 0.0275"/>
      <geometry>
        <cylinder length="0.055" radius="0.002"/>
      </geometry>
    </collision>
    <inertial>
      <origin rpy="0.0 0.0 0.0" xyz="0.0 0.0 0.0275"/>
      <mass value="0.005"/>
      <inertia ixx="1.2654166666666665e-06" ixy="0.0" ixz="0.0" iyy="1.2654166666666665e-06" iyz="0.0" izz="1e-08"/>
    </inertial>
  </link>
  <joint name="base_to_pillar_five_joint" type="fixed">
    <parent link="base_link"/>
    <child link="pillar_five_link"/>
    <origin rpy="0.0 0.0 0.0" xyz="-0.12 0.055 0.0"/>
  </joint>
  <gazebo reference="pillar_five_link">
    <material>Gazebo/Orange</material>
  </gazebo>
  <link name="pillar_six_link">
    <visual>
      <origin rpy="0.0 0.0 0.0" xyz="0.0 0.0 0.0275"/>
      <geometry>
        <cylinder length="0.055" radius="0.002"/>
      </geometry>
      <material name="pillar_color">
        <color rgba="1.0 0.4235294117647059 0.047058823529411764 1.0"/>
      </material>
    </visual>
    <collision>
      <origin rpy="0.0 0.0 0.0" xyz="0.0 0.0 0.0275"/>
      <geometry>
        <cylinder length="0.055" radius="0.002"/>
      </geometry>
    </collision>
    <inertial>
      <origin rpy="0.0 0.0 0.0" xyz="0.0 0.0 0.0275"/>
      <mass value="0.005"/>
      <inertia ixx="1.2654166666666665e-06" ixy="0.0" ixz="0.0" iyy="1.2654166666666665e-06" iyz="0.0" izz="1e-08"/>
    </inertial>
  </link>
  <joint name="base_to_pillar_six_joint" type="fixed">
    <parent link="base_link"/>
    <child link="pillar_six_link"/>
    <origin rpy="0.0 0.0 0.0" xyz="-0.12 -0.055 0.0"/>
  </joint>
  <gazebo reference="pillar_six_link">
    <material>Gazebo/Orange</material>
  </gazebo>
  <link name="upper_layer_link">
    <visual>
      <origin rpy="0 0 0" xyz="0 0 0"/>
      <geometry>
        <box size="0.255 0.088 0.002"/>
      </geometry>
      <material name="blue">
        <color rgba="0.0 0.2 1.0 1.0"/>
      </material>
    </visual>
    <visual name="direction_piece_1">
      <origin rpy="0.0 0.0 0.0" xyz="0.1125 0.0 0.001"/>
      <geometry>
        <box size="0.03 0.03 0.001"/>
      </geometry>
      <material name="header">
        <color rgba="1.0 0.0 0.0 1.0"/>
      </material>
    </visual>
    <visual name="direction_piece_2">
      <origin rpy="0.0 0.0 0.0" xyz="0.0825 0.028999999999999998 0.001"/>
      <geometry>
        <box size="0.03 0.03 0.001"/>
      </geometry>
      <material name="header">
        <color rgba="1.0 0.0 0.0 1.0"/>
      </material>
    </visual>
    <visual name="direction_piece_3">
      <origin rpy="0.0 0.0 0.0" xyz="0.0825 -0.028999999999999998 0.001"/>
      <geometry>
        <box size="0.03 0.03 0.002"/>
      </geometry>
      <material name="header">
        <color rgba="1.0 0.0 0.0 1.0"/>
      </material>
    </visual>
    <!-- Top left piece -->
    <visual>
      <origin rpy="0.0 0.0 0.0" xyz="0.1125 0.059 0"/>
      <geometry>
        <box size="0.03 0.03 0.002"/>
      </geometry>
      <material name="blue">
        <color rgba="0.0 0.2 1.0 1.0"/>
      </material>
    </visual>
    <!-- Top right piece -->
    <visual>
      <origin rpy="0.0 0.0 0.0" xyz="0.1125 -0.059 0"/>
      <geometry>
        <box size="0.03 0.03 0.002"/>
      </geometry>
      <material name="blue">
        <color rgba="0.0 0.2 1.0 1.0"/>
      </material>
    </visual>
    <!-- Middle left piece -->
    <visual>
      <origin rpy="0.0 0.0 0.0" xyz="0.0 0.059 0"/>
      <geometry>
        <box size="0.054 0.03 0.002"/>
      </geometry>
      <material name="blue">
        <color rgba="0.0 0.2 1.0 1.0"/>
      </material>
    </visual>
    <!-- Middle right piece -->
    <visual>
      <origin rpy="0.0 0.0 0.0" xyz="0.0 -0.059 0"/>
      <geometry>
        <box size="0.054 0.03 0.002"/>
      </geometry>
      <material name="blue">
        <color rgba="0.0 0.2 1.0 1.0"/>
      </material>
    </visual>
    <!-- Bottom left piece -->
    <visual>
      <origin rpy="0.0 0.0 0.0" xyz="-0.1125 0.059 0"/>
      <geometry>
        <box size="0.03 0.03 0.002"/>
      </geometry>
      <material name="blue">
        <color rgba="0.0 0.2 1.0 1.0"/>
      </material>
    </visual>
    <!-- Bottom right piece -->
    <visual>
      <origin rpy="0.0 0.0 0.0" xyz="-0.1125 -0.059 0"/>
      <geometry>
        <box size="0.03 0.03 0.002"/>
      </geometry>
      <material name="blue">
        <color rgba="0.0 0.2 1.0 1.0"/>
      </material>
    </visual>
    <collision>
      <origin rpy="0 0 0" xyz="0 0 0"/>
      <geometry>
        <box size="0.255 0.148 0.002"/>
      </geometry>
    </collision>
    <inertial>
      <origin rpy="0.0 0.0 0.0" xyz="0.0 0.0 0.0"/>
      <mass value="0.07"/>
      <inertia ixx="4.519666666666666e-05" ixy="0.0" ixz="0.0" iyy="0.0003793358333333334" iyz="0.0" izz="0.0004244858333333334"/>
    </inertial>
  </link>
  <joint name="base_to_upper_layer_joint" type="fixed">
    <parent link="base_link"/>
    <child link="upper_layer_link"/>
    <origin rpy="0 0 0" xyz="0 0 0.055"/>
  </joint>
  <gazebo reference="upper_layer_link">
    <material>Gazebo/Blue</material>
    <visual name="direction_piece_1">
      <material>
        <diffuse>0 0 0 1</diffuse>
      </material>
    </visual>
    <visual name="direction_piece_2">
      <material>Gazebo/Red</material>
    </visual>
    <visual name="direction_piece_3">
      <material>Gazebo/Red</material>
    </visual>
  </gazebo>
  <link name="front_left_wheel_link">
    <visual name="shaft">
      <origin xyz="0.0 0.0 -0.0155"/>
      <geometry>
        <cylinder length="0.02" radius="0.0025"/>
      </geometry>
      <material name="white">
        <color rgba="1.0 1.0 1.0 1.0"/>
      </material>
    </visual>
    <visual>
      <origin rpy="0.0 0.0 0.0" xyz="0.0 0.0 0.0"/>
      <geometry>
        <cylinder length="0.031" radius="0.03"/>
      </geometry>
      <material name="yellow">
        <color rgba="1.0 0.9294117647058824 0.1568627450980392 1.0"/>
      </material>
    </visual>
    <collision>
      <origin rpy="0 0 0" xyz="0 0 0"/>
      <geometry>
        <cylinder length="0.031" radius="0.03"/>
      </geometry>
    </collision>
    <inertial>
      <origin rpy="0 0 0" xyz="0 0 0"/>
      <mass value="0.04"/>
      <inertia ixx="1.2203333333333332e-05" ixy="0.0" ixz="0.0" iyy="1.2203333333333332e-05" iyz="0.0" izz="1.8e-05"/>
    </inertial>
  </link>
  <joint name="front_left_wheel_joint" type="continuous">
    <parent link="base_link"/>
    <child link="front_left_wheel_link"/>
    <origin rpy="-1.5707963267948966 0.0 0.0" xyz="0.06215 0.064 -0.009"/>
    <axis rpy="0 0 0" xyz="0 0 1"/>
    <limit effort="100" velocity="100"/>
    <joint_properties damping="0.0" friction="0.0"/>
  </joint>
  <gazebo reference="front_left_wheel_link">
    <material>Gazebo/Yellow</material>
  </gazebo>
  <link name="front_right_wheel_link">
    <visual name="shaft">
      <origin xyz="0.0 0.0 0.0155"/>
      <geometry>
        <cylinder length="0.02" radius="0.0025"/>
      </geometry>
      <material name="white">
        <color rgba="1.0 1.0 1.0 1.0"/>
      </material>
    </visual>
    <visual>
      <origin rpy="0.0 0.0 0.0" xyz="0.0 0.0 0.0"/>
      <geometry>
        <cylinder length="0.031" radius="0.03"/>
      </geometry>
      <material name="yellow">
        <color rgba="1.0 0.9294117647058824 0.1568627450980392 1.0"/>
      </material>
    </visual>
    <collision>
      <origin rpy="0 0 0" xyz="0 0 0"/>
      <geometry>
        <cylinder length="0.031" radius="0.03"/>
      </geometry>
    </collision>
    <inertial>
      <origin rpy="0 0 0" xyz="0 0 0"/>
      <mass value="0.04"/>
      <inertia ixx="1.2203333333333332e-05" ixy="0.0" ixz="0.0" iyy="1.2203333333333332e-05" iyz="0.0" izz="1.8e-05"/>
    </inertial>
  </link>
  <joint name="front_right_wheel_joint" type="continuous">
    <parent link="base_link"/>
    <child link="front_right_wheel_link"/>
    <origin rpy="-1.5707963267948966 0.0 0.0" xyz="0.06215 -0.064 -0.009"/>
    <axis rpy="0 0 0" xyz="0 0 1"/>
    <limit effort="100" velocity="100"/>
    <joint_properties damping="0.0" friction="0.0"/>
  </joint>
  <gazebo reference="front_right_wheel_link">
    <material>Gazebo/Yellow</material>
  </gazebo>
  <link name="back_left_wheel_link">
    <visual name="shaft">
      <origin xyz="0.0 0.0 -0.0155"/>
      <geometry>
        <cylinder length="0.02" radius="0.0025"/>
      </geometry>
      <material name="white">
        <color rgba="1.0 1.0 1.0 1.0"/>
      </material>
    </visual>
    <visual>
      <origin rpy="0.0 0.0 0.0" xyz="0.0 0.0 0.0"/>
      <geometry>
        <cylinder length="0.031" radius="0.03"/>
      </geometry>
      <material name="yellow">
        <color rgba="1.0 0.9294117647058824 0.1568627450980392 1.0"/>
      </material>
    </visual>
    <collision>
      <origin rpy="0 0 0" xyz="0 0 0"/>
      <geometry>
        <cylinder length="0.031" radius="0.03"/>
      </geometry>
    </collision>
    <inertial>
      <origin rpy="0 0 0" xyz="0 0 0"/>
      <mass value="0.04"/>
      <inertia ixx="1.2203333333333332e-05" ixy="0.0" ixz="0.0" iyy="1.2203333333333332e-05" iyz="0.0" izz="1.8e-05"/>
    </inertial>
  </link>
  <joint name="back_left_wheel_joint" type="continuous">
    <parent link="base_link"/>
    <child link="back_left_wheel_link"/>
    <origin rpy="-1.5707963267948966 0.0 0.0" xyz="-0.06215 0.064 -0.009"/>
    <axis rpy="0 0 0" xyz="0 0 1"/>
    <limit effort="100" velocity="100"/>
    <joint_properties damping="0.0" friction="0.0"/>
  </joint>
  <gazebo reference="back_left_wheel_link">
    <material>Gazebo/Yellow</material>
  </gazebo>
  <link name="back_right_wheel_link">
    <visual name="shaft">
      <origin xyz="0.0 0.0 0.0155"/>
      <geometry>
        <cylinder length="0.02" radius="0.0025"/>
      </geometry>
      <material name="white">
        <color rgba="1.0 1.0 1.0 1.0"/>
      </material>
    </visual>
    <visual>
      <origin rpy="0.0 0.0 0.0" xyz="0.0 0.0 0.0"/>
      <geometry>
        <cylinder length="0.031" radius="0.03"/>
      </geometry>
      <material name="yellow">
        <color rgba="1.0 0.9294117647058824 0.1568627450980392 1.0"/>
      </material>
    </visual>
    <collision>
      <origin rpy="0 0 0" xyz="0 0 0"/>
      <geometry>
        <cylinder length="0.031" radius="0.03"/>
      </geometry>
    </collision>
    <inertial>
      <origin rpy="0 0 0" xyz="0 0 0"/>
      <mass value="0.04"/>
      <inertia ixx="1.2203333333333332e-05" ixy="0.0" ixz="0.0" iyy="1.2203333333333332e-05" iyz="0.0" izz="1.8e-05"/>
    </inertial>
  </link>
  <joint name="back_right_wheel_joint" type="continuous">
    <parent link="base_link"/>
    <child link="back_right_wheel_link"/>
    <origin rpy="-1.5707963267948966 0.0 0.0" xyz="-0.06215 -0.064 -0.009"/>
    <axis rpy="0 0 0" xyz="0 0 1"/>
    <limit effort="100" velocity="100"/>
    <joint_properties damping="0.0" friction="0.0"/>
  </joint>
  <gazebo reference="back_right_wheel_link">
    <material>Gazebo/Yellow</material>
  </gazebo>
</robot>

